Workbook

Sheet GDP_US
A1: observation_date | B1: GDPC1
A2: 17168 | B2: 2182.681
A3: 17258 | B3: 2176.892
A4: 17349 | B4: 2172.432
A5: 17441 | B5: 2206.452
A6: 17533 | B6: 2239.682
A7: 17624 | B7: 2276.69
A8: 17715 | B8: 2289.77
A9: 17807 | B9: 2292.364
A10: 17899 | B10: 2260.807
A11: 17989 | B11: 2253.128
A12: 18080 | B12: 2276.424
A13: 18172 | B13: 2257.352
... A315: 45748 | B315: 23770.976

Sheet VIX
A1: observation_date | B1: VIXCLS
A2: 32874 | B2: 23.35
A3: 32905 | B3: 23.26
A4: 32933 | B4: 20.06
A5: 32964 | B5: 21.4
A6: 32994 | B6: 18.1
A7: 33025 | B7: 16.82
A8: 33055 | B8: 18.39
A9: 33086 | B9: 28.18
A10: 33117 | B10: 29.11
A11: 33147 | B11: 29.63
A12: 33178 | B12: 24.89
A13: 33208 | B13: 23.36
... A431: 45931 | B431: 18.09

Sheet MSCI_Europe
A1: Dates | B1: Price
A2: 36529 | B2: 135.7693
A3: 36530 | B3: 135.7693
A4: 36531 | B4: 135.7693
A5: 36532 | B5: 135.7693
A6: 36535 | B6: 135.7693
A7: 36536 | B7: 135.7693
A8: 36537 | B8: 135.7693
A9: 36538 | B9: 135.7693
A10: 36539 | B10: 135.7693
A11: 36542 | B11: 135.7693
A12: 36543 | B12: 135.7693
A13: 36544 | B13: 135.7693
... A6556: 45705 | B6556: 368.8843

Sheet EONIA
A1: Dates | B1: Prix
A2: 36890 | B2: 77.051137
A3: 36891 | B3: 77.051137
A4: 36892 | B4: 77.051137
A5: 36893 | B5: 77.051137
A6: 36894 | B6: 77.061478
A7: 36895 | B7: 77.071796
A8: 36896 | B8: 77.082092
A9: 36897 | B9: 77.112794
A10: 36898 | B10: 77.112794
A11: 36899 | B11: 77.112794
A12: 36900 | B12: 77.123012
A13: 36901 | B13: 77.133254
... A8817: 45706 | B8817: 106.24478

Sheet SP500
A1: Dates | B1: GSPC.Close
A2: 36526 | B2: 1394.46
A3: 36557 | B3: 1366.42
A4: 36586 | B4: 1498.58
A5: 36617 | B5: 1452.4301
A6: 36647 | B6: 1420.6
A7: 36678 | B7: 1454.6
A8: 36708 | B8: 1430.83
A9: 36739 | B9: 1517.6801
A10: 36770 | B10: 1436.51
A11: 36800 | B11: 1429.4
A12: 36831 | B12: 1314.95
A13: 36861 | B13: 1320.28
... A312: 45962 | B312: 6849.0898

Sheet TB3M
A1: observation_date | B1: TB3MS
A2: 36526 | B2: 5.32
A3: 36557 | B3: 5.55
A4: 36586 | B4: 5.69
A5: 36617 | B5: 5.66
A6: 36647 | B6: 5.79
A7: 36678 | B7: 5.69
A8: 36708 | B8: 5.96
A9: 36739 | B9: 6.09
A10: 36770 | B10: 6
A11: 36800 | B11: 6.11
A12: 36831 | B12: 6.17
A13: 36861 | B13: 5.77
... A312: 45962 | B312: 3.78

Sheet Excess_return
A1: Dates | B1: Excess_return
A2: 36557 | B2: =(('SP500'!B3-'SP500'!B2)/'SP500'!B2)*100 -(TB3M!B2/12) -> -2.4541417
A3: 36586 | B3: =(('SP500'!B4-'SP500'!B3)/'SP500'!B3)*100 -(TB3M!B3/12) -> 9.2094828
A4: 36617 | B4: =(('SP500'!B5-'SP500'!B4)/'SP500'!B4)*100 -(TB3M!B4/12) -> -3.5537422
A5: 36647 | B5: =(('SP500'!B6-'SP500'!B5)/'SP500'!B5)*100 -(TB3M!B5/12) -> -2.6631717
A6: 36678 | B6: =(('SP500'!B7-'SP500'!B6)/'SP500'!B6)*100 -(TB3M!B6/12) -> 1.910855
A7: 36708 | B7: =(('SP500'!B8-'SP500'!B7)/'SP500'!B7)*100 -(TB3M!B7/12) -> -2.1082943
A8: 36739 | B8: =(('SP500'!B9-'SP500'!B8)/'SP500'!B8)*100 -(TB3M!B8/12) -> 5.5732438
A9: 36770 | B9: =(('SP500'!B10-'SP500'!B9)/'SP500'!B9)*100 -(TB3M!B9/12) -> -5.8557975
A10: 36800 | B10: =(('SP500'!B11-'SP500'!B10)/'SP500'!B10)*100 -(TB3M!B10/12) -> -0.99494854
A11: 36831 | B11: =(('SP500'!B12-'SP500'!B11)/'SP500'!B11)*100 -(TB3M!B11/12) -> -8.5160277
A12: 36861 | B12: =(('SP500'!B13-'SP500'!B12)/'SP500'!B12)*100 -(TB3M!B12/12) -> -0.1088221
A13: 36892 | B13: =(('SP500'!B14-'SP500'!B13)/'SP500'!B13)*100 -(TB3M!B13/12) -> 2.9828243
... A311: 45962 | B311: =(('SP500'!B312-'SP500'!B311)/'SP500'!B311)*100 -(TB3M!B311/12) -> -0.18837152

Sheet US1Y
A1: observation_date | B1: DGS1
A2: 36528 | B2: 6.09
A3: 36529 | B3: 6
A4: 36530 | B4: 6.05
A5: 36531 | B5: 6.03
A6: 36532 | B6: 6
A7: 36535 | B7: 6.07
A8: 36536 | B8: 6.13
A9: 36537 | B9: 6.16
A10: 36538 | B10: 6.1
A11: 36539 | B11: 6.13
A12: 36542 | B12: 6.13
A13: 36543 | B13: 6.15
... A6770: 46002 | B6770: 3.56

Sheet US10Y
A1: observation_date | B1: DGS10
A2: 22648 | B2: 4.06
A3: 22649 | B3: 4.03
A4: 22650 | B4: 3.99
A5: 22651 | B5: 4.02
A6: 22654 | B6: 4.03
A7: 22655 | B7: 4.05
A8: 22656 | B8: 4.07
A9: 22657 | B9: 4.08
A10: 22658 | B10: 4.08
A11: 22661 | B11: 4.1
A12: 22662 | B12: 4.13
A13: 22663 | B13: 4.12
... A30: 22686 | B30: 4.05
A31: 22689
A32: 22690 | B32: 4.03
A33: 22691 | B33: 4.03
A34: 22692 | B34: 4.02
A35: 22693 | B35: 4.02
A36: 22696 | B36: 4.01
A37: 22697 | B37: 4.05
A38: 22698 | B38: 4.03
A39: 22699
A40: 22700 | B40: 4.02
A41: 22703 | B41: 4
A42: 22704 | B42: 4.01
A43: 22705 | B43: 4
A44: 22706 | B44: 3.98
A45: 22707 | B45: 3.98
A46: 22710 | B46: 4
A47: 22711 | B47: 4.01
A48: 22712 | B48: 4
A49: 22713 | B49: 3.98
A50: 22714 | B50: 3.96
A51: 22717 | B51: 3.94
... A79: 22755 | B79: 3.82
A80: 22756
A81: 22759 | B81: 3.86
A82: 22760 | B82: 3.87
A83: 22761 | B83: 3.88
...

Sheet WTI
A1: observation_date | B1: DCOILWTICO
A2: 31413 | B2: 22.93
A3: 31444 | B3: 15.45
A4: 31472 | B4: 12.61
A5: 31503 | B5: 12.84
A6: 31533 | B6: 15.38
A7: 31564 | B7: 13.43
A8: 31594 | B8: 11.58
A9: 31625 | B9: 15.1
A10: 31656 | B10: 14.87
A11: 31686 | B11: 14.9
A12: 31717 | B12: 15.22
A13: 31747 | B13: 16.11
... A480: 45962 | B480: 60.06
